Workbook

Sheet CRM – Zájemci
A1: TVŮJ ČLOVĚK — CRM Zájemci & Účastníci
A2: Jana Štěpaníková · NetWalking Pro · Všechny akce
A3: ◀ KLÍČOVÉ INFORMACE | H3: KONTAKT | J3: PROFIL | O3: PROCES & PLATBA | U3: GDPR & PROFILY | Z3: HODNOCENÍ PO AKCI ▶
A4: ID | B4: Datum přidání | C4: Jméno | D4: Příjmení | E4: Město bydliště | F4: Akce / Město | G4: Kompatibilita | H4: Telefon | I4: Email | J4: Věk | K4: Pohlaví | L4: Povolání | M4: Co hledá | N4: Koníčky | O4: Zdroj | P4: Stav | Q4: Schválen/a | R4: Zaplatil/a | S4: Cena zaplacena | T4: Poznámka | U4: GDPR souhlas | V4: Posl. kontakt | W4: Opak. účastník | X4: LinkedIn | Y4: Instagram | Z4: Hodnocení | AA4: Poznámka po akci
A5: 1 | B5: 09.03.2026 | C5: Jan | D5: Novák | E5: Ostrava | F5: Ostrava 23.4. | G5: Sedí s ID 3, 7 | H5: +420 777 123 456 | I5: jan@email.cz | J5: 42 | K5: Muž | L5: IT manažer | M5: Byznys partner | N5: Golf, AI, cestování | O5: LinkedIn | P5: Zájem | Q5: — | R5: — | U5: ✓ Souhlas | V5: 09.03.2026 | W5: ✗ Ne | X5: linkedin.com/in/novak
A6: 2 | B6: 09.03.2026 | C6: Petra | D6: Svobodová | E6: Opava | F6: Ostrava 23.4. | G6: Sedí s ID 5 | H6: +420 603 987 654 | I6: petra@firma.cz | J6: 35 | K6: Žena | L6: Podnikatelka | M6: Parťák na výlety | N6: Hory, jachting | O6: Osobní zpráva | P6: Pre-screen | Q6: — | R6: — | U6: ✓ Souhlas | V6: 09.03.2026 | W6: ✗ Ne | Y6: @petra.svobodova
A7: 3 | B7: 09.03.2026 | C7: Martin | D7: Horák | E7: Ostrava | F7: Ostrava 23.4. | G7: Sedí s ID 1, 2 | H7: +420 721 456 789 | I7: martin@horak.cz | J7: 48 | K7: Muž | L7: Ředitel | M7: Kombinace | N7: Golf, víno | O7: Honza Krkoška | P7: Zájem | Q7: — | R7: — | U7: ✓ Souhlas | V7: 09.03.2026 | W7: ✗ Ne

Sheet 📊 Dashboard
A1: TVŮJ ČLOVĚK — Přehled všech akcí
A3: ▌ Ostrava 23.4.
B4: Celkem přihlášených | C4: =COUNTIF('CRM – Zájemci'!F5:F104,"Ostrava 23.4.") -> 3
B5: Potvrzeno | C5: =COUNTIFS('CRM – Zájemci'!F5:F104,"Ostrava 23.4.",'CRM – Zájemci'!P5:P104,"Potvrzeno") -> 0
B6: Zaplatilo | C6: =COUNTIFS('CRM – Zájemci'!F5:F104,"Ostrava 23.4.",'CRM – Zájemci'!R5:R104,"✓ Ano") -> 0
B7: Čekací listina | C7: =COUNTIFS('CRM – Zájemci'!F5:F104,"Ostrava 23.4.",'CRM – Zájemci'!P5:P104,"Čekací listina") -> 0
A9: ▌ Ostrava květen
B10: Celkem přihlášených | C10: =COUNTIF('CRM – Zájemci'!F5:F104,"Ostrava květen") -> 0
B11: Potvrzeno | C11: =COUNTIFS('CRM – Zájemci'!F5:F104,"Ostrava květen",'CRM – Zájemci'!P5:P104,"Potvrzeno") -> 0
B12: Zaplatilo | C12: =COUNTIFS('CRM – Zájemci'!F5:F104,"Ostrava květen",'CRM – Zájemci'!R5:R104,"✓ Ano") -> 0
B13: Čekací listina | C13: =COUNTIFS('CRM – Zájemci'!F5:F104,"Ostrava květen",'CRM – Zájemci'!P5:P104,"Čekací listina") -> 0
A15: ▌ Ostrava červen
B16: Celkem přihlášených | C16: =COUNTIF('CRM – Zájemci'!F5:F104,"Ostrava červen") -> 0
B17: Potvrzeno | C17: =COUNTIFS('CRM – Zájemci'!F5:F104,"Ostrava červen",'CRM – Zájemci'!P5:P104,"Potvrzeno") -> 0
B18: Zaplatilo | C18: =COUNTIFS('CRM – Zájemci'!F5:F104,"Ostrava červen",'CRM – Zájemci'!R5:R104,"✓ Ano") -> 0
B19: Čekací listina | C19: =COUNTIFS('CRM – Zájemci'!F5:F104,"Ostrava červen",'CRM – Zájemci'!P5:P104,"Čekací listina") -> 0
A21: ▌ Praha červen
B22: Celkem přihlášených | C22: =COUNTIF('CRM – Zájemci'!F5:F104,"Praha červen") -> 0
B23: Potvrzeno | C23: =COUNTIFS('CRM – Zájemci'!F5:F104,"Praha červen",'CRM – Zájemci'!P5:P104,"Potvrzeno") -> 0
B24: Zaplatilo | C24: =COUNTIFS('CRM – Zájemci'!F5:F104,"Praha červen",'CRM – Zájemci'!R5:R104,"✓ Ano") -> 0
B25: Čekací listina | C25: =COUNTIFS('CRM – Zájemci'!F5:F104,"Praha červen",'CRM – Zájemci'!P5:P104,"Čekací listina") -> 0
A27: ▌ Praha červenec
B28: Celkem přihlášených | C28: =COUNTIF('CRM – Zájemci'!F5:F104,"Praha červenec") -> 0
B29: Potvrzeno | C29: =COUNTIFS('CRM – Zájemci'!F5:F104,"Praha červenec",'CRM – Zájemci'!P5:P104,"Potvrzeno") -> 0
B30: Zaplatilo | C30: =COUNTIFS('CRM – Zájemci'!F5:F104,"Praha červenec",'CRM – Zájemci'!R5:R104,"✓ Ano") -> 0
B31: Čekací listina | C31: =COUNTIFS('CRM – Zájemci'!F5:F104,"Praha červenec",'CRM – Zájemci'!P5:P104,"Čekací listina") -> 0
A33: ▌ Brno jaro
B34: Celkem přihlášených | C34: =COUNTIF('CRM – Zájemci'!F5:F104,"Brno jaro") -> 0
B35: Potvrzeno | C35: =COUNTIFS('CRM – Zájemci'!F5:F104,"Brno jaro",'CRM – Zájemci'!P5:P104,"Potvrzeno") -> 0
B36: Zaplatilo | C36: =COUNTIFS('CRM – Zájemci'!F5:F104,"Brno jaro",'CRM – Zájemci'!R5:R104,"✓ Ano") -> 0
B37: Čekací listina | C37: =COUNTIFS('CRM – Zájemci'!F5:F104,"Brno jaro",'CRM – Zájemci'!P5:P104,"Čekací listina") -> 0
A39: ▌ Brno podzim
B40: Celkem přihlášených | C40: =COUNTIF('CRM – Zájemci'!F5:F104,"Brno podzim") -> 0
B41: Potvrzeno | C41: =COUNTIFS('CRM – Zájemci'!F5:F104,"Brno podzim",'CRM – Zájemci'!P5:P104,"Potvrzeno") -> 0
B42: Zaplatilo | C42: =COUNTIFS('CRM – Zájemci'!F5:F104,"Brno podzim",'CRM – Zájemci'!R5:R104,"✓ Ano") -> 0
B43: Čekací listina | C43: =COUNTIFS('CRM – Zájemci'!F5:F104,"Brno podzim",'CRM – Zájemci'!P5:P104,"Čekací listina") -> 0
A45: ▌ Moře září 2026
B46: Celkem přihlášených | C46: =COUNTIF('CRM – Zájemci'!F5:F104,"Moře září 2026") -> 0
B47: Potvrzeno | C47: =COUNTIFS('CRM – Zájemci'!F5:F104,"Moře září 2026",'CRM – Zájemci'!P5:P104,"Potvrzeno") -> 0
B48: Zaplatilo | C48: =COUNTIFS('CRM – Zájemci'!F5:F104,"Moře září 2026",'CRM – Zájemci'!R5:R104,"✓ Ano") -> 0
...

Sheet 🍽️ Catering brief
A1: CATERING BRIEF — Tvůj člověk, 23. dubna 2026, Ostrava
A3: Počet hostů | B3: 40–50 lidí
A4: Čas akce | B4: 17:00 – 22:00
A5: Typ cateringu | B5: Raut — průběžný švédský stůl (ne plnohodnotná večeře)
A6: Studené občerstvení | B6: Kanapky, sýry, uzeniny, zelenina, dipy, pečivo
A7: Teplé věci | B7: Drobné teplé pochutiny — mini quiche, plněné houby apod.
A8: Nealko nápoje | B8: Voda, džusy, limonády, káva, čaj — po celou dobu
A9: Alkohol | B9: Bílé víno, červené víno, pivo, prosecco na přivítání
A10: Čas výdeje | B10: Průběžně od 16:00 do 21:30
A11: Dietní omezení | B11: Zjistit při registraci — políčko ve formuláři
A12: Personál po 18:00 | B12: ← DOPLNIT cenu po úterním hovoru s Honzou
A13: Orientační cena/os. | B13: ← DOPLNIT po nacenění
A14: Celkový odhad | B14: ← Počet hostů × cena/os.
A15: Poznámka | B15: Žádné těžké jídlo — akce trvá 6 hodin, lidé by neměli být ospalí
